2021-08-09 12:07:49 INFO     Starting
2021-08-09 12:07:49 INFO     Begin reading in file
2021-08-09 12:07:49 ERROR    Exception in main(): 
Traceback (most recent call last):
  File "/scratch/groups/horence/kaitlin/spliz_nextflow/nf-core-spliz/bin/calc_splizvd.py", line 483, in <module>
    exit(main())
  File "/scratch/groups/horence/kaitlin/spliz_nextflow/nf-core-spliz/bin/calc_splizvd.py", line 145, in main
    df = pd.read_csv(args.input, sep="\t")
  File "/home/users/kaitlin3/anaconda3/lib/python3.8/site-packages/pandas/io/parsers.py", line 686, in read_csv
    return _read(filepath_or_buffer, kwds)
  File "/home/users/kaitlin3/anaconda3/lib/python3.8/site-packages/pandas/io/parsers.py", line 452, in _read
    parser = TextFileReader(fp_or_buf, **kwds)
  File "/home/users/kaitlin3/anaconda3/lib/python3.8/site-packages/pandas/io/parsers.py", line 946, in __init__
    self._make_engine(self.engine)
  File "/home/users/kaitlin3/anaconda3/lib/python3.8/site-packages/pandas/io/parsers.py", line 1178, in _make_engine
    self._engine = CParserWrapper(self.f, **self.options)
  File "/home/users/kaitlin3/anaconda3/lib/python3.8/site-packages/pandas/io/parsers.py", line 2008, in __init__
    self._reader = parsers.TextReader(src, **kwds)
  File "pandas/_libs/parsers.pyx", line 382, in pandas._libs.parsers.TextReader.__cinit__
  File "pandas/_libs/parsers.pyx", line 674, in pandas._libs.parsers.TextReader._setup_parser_source
FileNotFoundError: [Errno 2] No such file or directory: 'Ott_ann_splices.tsv'
